Workbook

Sheet README
A1: PangAsin – Estimated Municipal Salt Production and Salt-Bed Counts
A2: Educated-estimate (synthetic) dataset for the seven salt-producing municipalities of Pangasinan. Companion to the Word documentation.
A4: Purpose | B4: Monthly salt production (kg) per municipality for 2024 and 2025, and estimated number of salt beds per municipality, derived from the San Fabian primary record and BFAR RFO1 FOI data (Bani uses FOI by default; its master-sheet reports are a selectable alternative).
A5: How the numbers are built | B5: 1) Annual production = primary value if one exists, otherwise FOI value (Annual_Production). 2) Salt beds = annual production ÷ x, where x = kg of salt per bed per year calibrated on Alaminos City 2025 (Alaminos_Beds, Salt_Beds). 3) Monthly production = annual production × monthly share (Seasonal_Profile, Shares, Monthly_Estimates).
A6: Colour code | B6: Blue text = hard-coded input from a source file. Black = formula. Green = direct link to another sheet. Yellow fill = selector you can change (Assumptions!B4, B5).
A7: Real monthly data | B7: If you have observed monthly production for any municipality-year, type it into Monthly_Override (kg). It replaces the estimate for that row. Assumptions!B10 changes how Bani and San Fabian are spread inside their season (1 = equal months, 2 = observed profile).
A8: Alaminos and San Fabian sources | B8: Assumptions!B23: Alaminos annual production = master col. U (read as kg per month) × 6 months (2, default) or FOI (1). The master sheet leaves Alaminos annual production empty; Alaminos_Beds column J fills it per farm. Assumptions!B24: San Fabian hybrid series – primary where it exists, FOI fills missing years. San Fabian 2023–2026 is in Annual_Production rows 35–42 and Monthly_Estimates rows 30–35; every month has a value (equation 5a), and the recorded Nov–May season is a switch (Assumptions!C19).
A9: KEY WARNING 4 | B9: Master-sheet column U is labelled 'per day' but is used as kg per month: that reading matches FOI within 2.8% (Testing T10), while column V (U × 30) is 31× FOI. Confirm the unit with the source. Alaminos primary values carry no year, so they are applied to 2025 only.
A10: Selectors (Assumptions) | B10: B11 chooses Bani's annual source (1 = FOI, default; 2 = primary master sheet). B4 chooses the bed-yield basis (1 = Alaminos 2025, 2 = mean of 2025 and 2026, 3 = legacy 310.61 from the handwritten card). B5 chooses the monthly method (1 = same-year observed provincial profile + primary season windows, 2 = pooled 2024–25 profile + windows, 3 = linear arithmetic with M1 = 8%). Column B of the municipality table is an optional coverage multiplier (default 1.00).
A11: KEY WARNING 1 | B11: The handwritten calibration divides by 3,444 salt beds. That count equals only the first 21 Alaminos rows of the master sheet (cumulative total, Alaminos_Beds). The full sheet has 7,410 beds, so x = 144.36 kg/bed/yr, not 310.61. The workbook defaults to the full sheet; set Assumptions!B4 = 3 to reproduce the handwritten basis.
A12: KEY WARNING 2 | B12: FOI figures are lower bounds. Where primary data exist, FOI covers 7% (Bani) to 93% (San Fabian) of them, and the FOI provincial 2025 total is about 15% of the 2021 OPAg total (Testing, T9). Use the coverage multiplier if better municipal totals become available.
A13: KEY WARNING 3 | B13: These are deterministic disaggregations of annual totals. Monthly values contain no information beyond the annual total and the seasonal profile, so they illustrate and test the PangAsin pipeline but are not observed data. Do not report them as measurements.
A14: Sheets | B14: Assumptions · Monthly_Override · Annual_Production · Alaminos_Beds · Salt_Beds · Seasonal_Profile · Shares · Monthly_Estimates · Monthly_Long (database-ready) · Testing (T1–T10, live formulas).
A15: Sources | B15: Primary: salt_MasterSheet1 (Bani, Alaminos City); San Fabian email screenshots; handwritten calculation cards. Secondary: BFAR RFO1 FOI files RS3969 and RS4760. External benchmark (Testing T3, T9): Pangasinan Provincial Government / OPAg 2021 figures, https://www.pangasinan.gov.ph/?p=108708
... A18: 2026 San Fabian-reference synthesis | B18: This updated _IQR_2026 copy adds synthetic Jan-Sep 2026 monthly values for all seven municipalities using the San Fabian 2026 estimated profile plus stochastic IQR variation. Each municipality total reconciles to the supplied Jan-Sep 2026 production amount; Oct-Dec are not included. See the 2026_ tabs.

Sheet Assumptions
A1: Assumptions and selectors
A2: Yellow cells are selectors. Everything downstream recalculates.
A3: Parameter | B3: Value | C3: Notes
A4: Bed-yield basis x (1 = Alaminos 2025 FOI · 2 = mean of 2025 & 2026 FOI · 3 = legacy 310.61 · 4 = Alaminos primary col. U) | B4: 1 | C4: Default 1: complete-year FOI figure with a surveyed bed count. Option 4 calibrates on the primary master-sheet production instead (B26); the two agree within 3%.
A5: Monthly method (1 = same-year observed profile + windows · 2 = pooled 2024–25 profile + windows · 3 = linear arithmetic) | B5: 1 | C5: Default 1. Method 3 reproduces the handwritten 'M1 = 8%, linear arithmetic' idea for comparison.
A6: Linear arithmetic first-month share a1 | B6: 0.08 | C6: From handwritten card: M1 = 8% of total yearly production.
A7: Bed yield x used (kg / salt bed / year) | B7: =CHOOSE(B4,Alaminos_Beds!B9,AVERAGE(Alaminos_Beds!B9,Alaminos_Beds!B10),Alaminos_Beds!B12,B26) | C7: Calculated with CHOOSE on the selector: Alaminos 2025, mean of 2025 and 2026, or legacy.
A8: Average bed area, Alaminos survey (m²) | B8: =Alaminos_Beds!B6 | C8: Bed-count-weighted mean of the 38 Alaminos survey rows.
A9: Legacy bed count used on handwritten card | B9: 3444 | C9: Handwritten x = 1,069,740 ÷ 3,444 = 310.61. Equals cumulative beds through row 21 of the Alaminos table, not the full sheet.
A10: Shape inside a primary window (1 = flat · 2 = follow the observed profile) | B10: 1 | C10: Applies to Bani and San Fabian. 1 = equal months (default, no monthly evidence). 2 = months weighted by the observed provincial profile (puts ~86% of Bani output in April). Real monthly data in Monthly_Override replace both.
A11: Bani annual source (1 = FOI, like the other municipalities · 2 = primary master sheet) | B11: 1 | C11: Default 1. Option 2 uses the master-sheet farm reports (9,445 MT in 2024, 8,160 MT in 2025) and applies Bani's recorded Jan–Apr production window.
A12: Municipality | B12: Coverage multiplier c | C12: Use primary season window (1/0) | D12: Jan | E12: Feb | F12: Mar | G12: Apr | H12: May | I12: Jun | J12: Jul | K12: Aug | L12: Sep | M12: Oct | N12: Nov | O12: Dec | P12: Window source / note
A13: Alaminos City | B13: 1 | C13: 0 | D13: 1 | E13: 1 | F13: 1 | G13: 1 | H13: 1 | I13: 0 | J13: 0 | K13: 0 | L13: 0 | M13: 0 | N13: 0 | O13: 1 | P13: Primary season Dec–May is stored in the flags. Default 0 = observed profile like the other municipalities; set C13 = 1 for flat monthly rates in Dec–May only.
A14: Anda | B14: 1 | C14: 0 | D14: 1 | E14: 1 | F14: 1 | G14: 1 | H14: 1 | I14: 1 | J14: 1 | K14: 1 | L14: 1 | M14: 1 | N14: 1 | O14: 1 | P14: No primary season data – provincial profile applies.
A15: Bani | B15: 1 | C15: =IF($B$11=2,1,0) | D15: 1 | E15: 1 | F15: 1 | G15: 1 | H15: 0 | I15: 0 | J15: 0 | K15: 0 | L15: 0 | M15: 0 | N15: 0 | O15: 0 | P15: Master sheet: Nov–Dec pond preparation, Jan–Apr production period.
A16: Bolinao | B16: 1 | C16: 0 | D16: 1 | E16: 1 | F16: 1 | G16: 1 | H16: 1 | I16: 1 | J16: 1 | K16: 1 | L16: 1 | M16: 1 | N16: 1 | O16: 1 | P16: No primary season data – provincial profile applies.
A17: Dasol | B17: 1 | C17: 0 | D17: 1 | E17: 1 | F17: 1 | G17: 1 | H17: 1 | I17: 1 | J17: 1 | K17: 1 | L17: 1 | M17: 1 | N17: 1 | O17: 1 | P17: No primary season data – provincial profile applies.
A18: Infanta | B18: 1 | C18: 0 | D18: 1 | E18: 1 | F18: 1 | G18: 1 | H18: 1 | I18: 1 | J18: 1 | K18: 1 | L18: 1 | M18: 1 | N18: 1 | O18: 1 | P18: No primary season data – provincial profile applies.
A19: San Fabian | B19: 1 | C19: 0 | D19: 1 | E19: 1 | F19: 1 | G19: 1 | H19: 1 | I19: 0 | J19: 0 | K19: 0 | L19: 0 | M19: 0 | N19: 1 | O19: 1 | P19: Primary season Nov–May is stored in the flags. Default 0 = observed profile (no empty months); set C19 = 1 to confine output to Nov–May.
A21: Coverage multiplier: leave at 1.00 unless a better municipal annual total becomes available (it multiplies the selected annual production). Flags are only used where 'Use primary season window' = 1.
A22: Additional selectors
A23: Alaminos annual source (1 = FOI · 2 = master col. U, read as kg per month, × season months) | B23: 2 | C23: Default 2 (primary): 183,210 kg a month × 6 months (Dec–May) = 1,099,260 kg, 2.8% above FOI. 2025 only. See Testing T10 for the unit reading.
A24: San Fabian fill for years with no primary value (1 = FOI as reported · 2 = FOI × primary ÷ FOI ratio of overlapping years) | B24: 1 | C24: Hybrid series: primary where it exists, otherwise FOI (2026 primary is 'ongoing'). Option 2 scales FOI up by the 2024–25 overlap ratio.
A25: Alaminos season months (Σ of its window flags, row 13) | B25: =SUM(D13:O13) | C25: Dec–May = 6 months.
A26: x from primary Alaminos production (col. U × season months ÷ beds) | B26: =Alaminos_Beds!B14*B25/Alaminos_Beds!B4 | C26: Used only when B4 = 4.

Sheet Alaminos_Beds
A1: Alaminos City salt-bed census and bed-yield calibration
A2: Source: salt_MasterSheet1, rows 11–48 (primary data).
A4: Σ salt beds, full master sheet | B4: =SUM(D16:D53)
A5: Σ bed area (ha) | B5: =SUM(G16:G53)
A6: Weighted average bed area (m²) | B6: =SUMPRODUCT(D16:D53,F16:F53)/B4
A7: FOI Alaminos City 2025 (kg) | B7: =Annual_Production!C4
A8: FOI Alaminos City 2026 (kg, provisional) | B8: =Annual_Production!D4
A9: x 2025 = FOI 2025 ÷ Σ beds (kg/bed/yr) | B9: =B7/B4
A10: x 2026 (provisional) = FOI 2026 ÷ Σ beds | B10: =B8/B4
A11: Legacy bed count (handwritten card) | B11: =Assumptions!B9
A12: x legacy = FOI 2025 ÷ legacy count | B12: =B7/B11
A13: Farm at which cumulative beds first equal the legacy count | B13: =IFERROR(INDEX(C16:C53,MATCH(B11,H16:H53,0)),"no exact match")
A14: Σ master col. U (kg; read as per month) | B14: =SUM(I16:I53)
A15: # | B15: Barangay | C15: Farm / operator | D15: Salt beds | E15: Bed size (ft) | F15: Bed area (m²) | G15: Bed area (ha) | H15: Cumulative beds | I15: Production per month, master col. U (kg) | J15: Annual 2025 = U × season months (kg) | K15: Annual 2025 (MT)
A16: 1 | B16: Mona | C16: Aurelia Alejo | D16: 143 | E16: 18 x 20 | F16: 33.45 | G16: =D16*F16/10000 | H16: =SUM(D$16:D16) | I16: 2860 | J16: =I16*Assumptions!$B$25 | K16: =J16/1000
A17: 2 | B17: Mona | C17: Jacqueline M. Capiral (Mariano S. Montemayor, Jr.) | D17: 250 | E17: 18 x 20 | F17: 33.45 | G17: =D17*F17/10000 | H17: =SUM(D$16:D17) | I17: 6250 | J17: =I17*Assumptions!$B$25 | K17: =J17/1000
A18: 3 | B18: Mona | C18: Jerry R. De Vera | D18: 113 | E18: 18 x 20 | F18: 33.45 | G18: =D18*F18/10000 | H18: =SUM(D$16:D18) | I18: 2825 | J18: =I18*Assumptions!$B$25 | K18: =J18/1000
A19: 4 | B19: Mona | C19: Percebal Carbonel | D19: 65 | E19: 20 x 20 | F19: 37.16 | G19: =D19*F19/10000 | H19: =SUM(D$16:D19) | I19: 1300 | J19: =I19*Assumptions!$B$25 | K19: =J19/1000
A20: 5 | B20: Mona | C20: 4 Salt Farmer Unsurveyed | D20: 400 | E20: 18 x 20 | F20: 33.45 | G20: =D20*F20/10000 | H20: =SUM(D$16:D20) | I20: 10000 | J20: =I20*Assumptions!$B$25 | K20: =J20/1000
A21: 6 | B21: Pandan | C21: Concepcion Legaspi Nato | D21: 513 | E21: 18 x 20 | F21: 33.45 | G21: =D21*F21/10000 | H21: =SUM(D$16:D21) | I21: 10260 | J21: =I21*Assumptions!$B$25 | K21: =J21/1000
A22: 7 | B22: Pandan | C22: Crisanto R. Legaspi | D22: 145 | E22: 18 x 20 | F22: 33.45 | G22: =D22*F22/10000 | H22: =SUM(D$16:D22) | I22: 2900 | J22: =I22*Assumptions!$B$25 | K22: =J22/1000
A23: 8 | B23: Pandan | C23: Ricardo D. Legaspi | D23: 60 | E23: 18 x 20 | F23: 33.45 | G23: =D23*F23/10000 | H23: =SUM(D$16:D23) | I23: 1200 | J23: =I23*Assumptions!$B$25 | K23: =J23/1000
A24: 9 | B24: Pandan | C24: Salvador Braganza | D24: 130 | E24: 18 x 20 | F24: 33.45 | G24: =D24*F24/10000 | H24: =SUM(D$16:D24) | I24: 2600 | J24: =I24*Assumptions!$B$25 | K24: =J24/1000
A25: 10 | B25: Pandan | C25: Salvador R. Legaspi | D25: 90 | E25: 18 x 20 | F25: 33.45 | G25: =D25*F25/10000 | H25: =SUM(D$16:D25) | I25: 1800 | J25: =I25*Assumptions!$B$25 | K25: =J25/1000
A26: 11 | B26: Pangapisan | C26: Bobby G. Bautista | D26: 150 | E26: 18 x 20 | F26: 33.45 | G26: =D26*F26/10000 | H26: =SUM(D$16:D26) | I26: 2250 | J26: =I26*Assumptions!$B$25 | K26: =J26/1000
A27: 12 | B27: Pangapisan | C27: Christopher De Guzman | D27: 140 | E27: 18 x 20 | F27: 33.45 | G27: =D27*F27/10000 | H27: =SUM(D$16:D27) | I27: 3500 | J27: =I27*Assumptions!$B$25 | K27: =J27/1000
... A53: 38 | B53: Pangapisan | C53: 3 Unsurveyed Salt Farmer | D53: 300 | E53: 18 x 20 | F53: 33.45 | G53: =D53*F53/10000 | H53: =SUM(D$16:D53) | I53: 7500 | J53: =I53*Assumptions!$B$25 | K53: =J53/1000
A54: Total | D54: =SUM(D16:D53) | G54: =SUM(G16:G53) | I54: =SUM(I16:I53) | J54: =SUM(J16:J53) | K54: =SUM(K16:K53)
A55: Master sheet labels column U 'per day'. It is read here as kg per month; the sheet's own column V (= U × 30) is not used (Testing T10). The sheet leaves Alaminos annual production empty; column J fills it.

Sheet Annual_Production
A1: Annual production by municipality – source selection
A2: Rule: primary value if available, otherwise FOI (BFAR RFO1). Units: kg.
A3: Municipality | B3: FOI 2024 | C3: FOI 2025 | D3: FOI 2026 (provisional) | E3: Primary 2024 | F3: Primary 2025 | G3: Selected 2024 | H3: Selected 2025 | I3: Source 2024 | J3: Source 2025 | K3: Coverage multiplier | L3: Used 2024 | M3: Used 2025 | N3: Note
A4: Alaminos City | B4: 446350 | C4: 1069740 | D4: 1327670 | F4: =IF(Assumptions!B23=2,Alaminos_Beds!B14*Assumptions!B25,"") | G4: =IF(ISNUMBER(E4),E4,B4) | H4: =IF(ISNUMBER(F4),F4,C4) | I4: =IF(ISNUMBER(E4),"Primary","FOI (secondary)") | J4: =IF(ISNUMBER(F4),"Primary","FOI (secondary)") | K4: =Assumptions!B13 | L4: =G4*K4 | M4: =H4*K4 | N4: 2025 default (Assumptions!B23 = 2): primary master col. U (kg/month) × 6 months, 2.8% above FOI. 2024 stays FOI. B23 = 1 gives FOI.
A5: Anda | B5: 115600 | C5: 1332211 | D5: 1510686 | G5: =IF(ISNUMBER(E5),E5,B5) | H5: =IF(ISNUMBER(F5),F5,C5) | I5: =IF(ISNUMBER(E5),"Primary","FOI (secondary)") | J5: =IF(ISNUMBER(F5),"Primary","FOI (secondary)") | K5: =Assumptions!B14 | L5: =G5*K5 | M5: =H5*K5 | N5: FOI only.
A6: Bani | B6: 649400 | C6: 607800 | D6: 73500 | E6: =IF(Assumptions!B11=2,C23*1000,"") | F6: =IF(Assumptions!B11=2,D23*1000,"") | G6: =IF(ISNUMBER(E6),E6,B6) | H6: =IF(ISNUMBER(F6),F6,C6) | I6: =IF(ISNUMBER(E6),"Primary","FOI (secondary)") | J6: =IF(ISNUMBER(F6),"Primary","FOI (secondary)") | K6: =Assumptions!B15 | L6: =G6*K6 | M6: =H6*K6 | N6: FOI by default (Assumptions!B11 = 1). Master-sheet primary (9,445 / 8,160 MT) is available as option 2; its 2025 values equal exactly 40 t/ha × area.
A7: Bolinao | B7: 21825 | C7: 4461917 | D7: 10420307 | G7: =IF(ISNUMBER(E7),E7,B7) | H7: =IF(ISNUMBER(F7),F7,C7) | I7: =IF(ISNUMBER(E7),"Primary","FOI (secondary)") | J7: =IF(ISNUMBER(F7),"Primary","FOI (secondary)") | K7: =Assumptions!B16 | L7: =G7*K7 | M7: =H7*K7 | N7: FOI only; 2024→2025 jump of ×204 indicates reporting expansion, not growth.
A8: Dasol | B8: 579267 | C8: 776414 | D8: 629511 | G8: =IF(ISNUMBER(E8),E8,B8) | H8: =IF(ISNUMBER(F8),F8,C8) | I8: =IF(ISNUMBER(E8),"Primary","FOI (secondary)") | J8: =IF(ISNUMBER(F8),"Primary","FOI (secondary)") | K8: =Assumptions!B17 | L8: =G8*K8 | M8: =H8*K8 | N8: FOI only; ~3% of OPAg 2021 level (Testing T9).
A9: Infanta | B9: 357916 | C9: 1436623 | D9: 928140 | G9: =IF(ISNUMBER(E9),E9,B9) | H9: =IF(ISNUMBER(F9),F9,C9) | I9: =IF(ISNUMBER(E9),"Primary","FOI (secondary)") | J9: =IF(ISNUMBER(F9),"Primary","FOI (secondary)") | K9: =Assumptions!B18 | L9: =G9*K9 | M9: =H9*K9 | N9: FOI only.
A10: San Fabian | B10: 96000 | C10: 70495 | D10: 91975 | E10: =B30*1000 | F10: =B31*1000 | G10: =IF(ISNUMBER(E10),E10,B10) | H10: =IF(ISNUMBER(F10),F10,C10) | I10: =IF(ISNUMBER(E10),"Primary","FOI (secondary)") | J10: =IF(ISNUMBER(F10),"Primary","FOI (secondary)") | K10: =Assumptions!B19 | L10: =G10*K10 | M10: =H10*K10 | N10: Primary = email screenshots (cooked salt, Tiblong).
A11: Total | B11: =SUM(B4:B10) | C11: =SUM(C4:C10) | D11: =SUM(D4:D10) | G11: =SUM(G4:G10) | H11: =SUM(H4:H10) | L11: =SUM(L4:L10) | M11: =SUM(M4:M10)
A12: Published FOI totals | B12: 2266358 | C12: 9755200 | D12: 14981789
A13: Check (computed − published) | B13: =B11-B12 | C13: =C11-C12 | D13: =D11-D12
A16: Bani – primary farm reports (master sheet rows 4–8)
A17: Farm | B17: Total area (ha) | C17: 2024 (MT) | D17: 2025 (MT) | E17: 2024 (t/ha) | F17: 2025 (t/ha)
A18: Borlongan Aqua Farm / Hernandez Salt Farm | B18: 48 | C18: 2160 | D18: 1920 | E18: =IF(C18>0,C18/B18,"") | F18: =IF(D18>0,D18/B18,"")
A19: Salud Ilao Salt Farm | B19: 12 | C19: 238.49 | D19: 480 | E19: =IF(C19>0,C19/B19,"") | F19: =IF(D19>0,D19/B19,"")
A20: Armida Salt Farm | B20: 38 | C20: 1505.56 | D20: 1520 | E20: =IF(C20>0,C20/B20,"") | F20: =IF(D20>0,D20/B20,"")
A21: Abesamins Salt Farm | B21: 106 | C21: 5064.64 | D21: 4240 | E21: =IF(C21>0,C21/B21,"") | F21: =IF(D21>0,D21/B21,"")
A22: Aquino Mudsalt | B22: 7 | C22: 476 | D22: 0 | E22: =IF(C22>0,C22/B22,"") | F22: =IF(D22>0,D22/B22,"")
A23: Total | B23: =SUM(B18:B22) | C23: =SUM(C18:C22) | D23: =SUM(D18:D22)
A24: Active area 2025 (farms with 2025 output > 0) | B24: =SUMIF(D18:D22,">0",B18:B22)
A25: Aquino Mudsalt recorded 'Stop operation (2025)' – entered as 0 MT for 2025.
A27: San Fabian (Tiblong) – primary records from email screenshots
A28: Year | B28: Production (MT) | C28: Production area (ha) | D28: Note
A29: 2023 | B29: 84 | C29: 0.04
A30: 2024 | B30: 103.5 | C30: 0.04
A31: 2025 | B31: 106 | C31: 0.06
A32: 2026 | C32: 0.06 | D32: Ongoing data collection
A33: Method: cooked salt / brine boiling · Season: November–May · 2 operators · email states '97 MT ave.' (mean of 2023–2025 = 97.8 MT).
A35: San Fabian hybrid series – primary where available, FOI fills missing values
A36: Year | B36: Primary (kg) | C36: FOI (kg) | D36: Hybrid used (kg) | E36: Basis | F36: Note
A37: 2023 | B37: =IF(ISNUMBER(B29),B29*1000,"") | D37: =IF(ISNUMBER(B37),B37,IF(ISNUMBER(C37),IF(Assumptions!$B$24=2,C37*$B$42,C37),"")) | E37: =IF(ISNUMBER(B37),"Primary",IF(ISNUMBER(C37),IF(Assumptions!$B$24=2,"FOI scaled (fill)","FOI as reported (fill)"),"missing")) | F37: No FOI value; primary only
A38: 2024 | B38: =IF(ISNUMBER(B30),B30*1000,"") | C38: =B10 | D38: =IF(ISNUMBER(B38),B38,IF(ISNUMBER(C38),IF(Assumptions!$B$24=2,C38*$B$42,C38),"")) | E38: =IF(ISNUMBER(B38),"Primary",IF(ISNUMBER(C38),IF(Assumptions!$B$24=2,"FOI scaled (fill)","FOI as reported (fill)"),"missing")) | F38: Both available; primary used
A39: 2025 | B39: =IF(ISNUMBER(B31),B31*1000,"") | C39: =C10 | D39: =IF(ISNUMBER(B39),B39,IF(ISNUMBER(C39),IF(Assumptions!$B$24=2,C39*$B$42,C39),"")) | E39: =IF(ISNUMBER(B39),"Primary",IF(ISNUMBER(C39),IF(Assumptions!$B$24=2,"FOI scaled (fill)","FOI as reported (fill)"),"missing")) | F39: Both available; primary used
A40: 2026 | B40: =IF(ISNUMBER(B32),B32*1000,"") | C40: =D10 | D40: =IF(ISNUMBER(B40),B40,IF(ISNUMBER(C40),IF(Assumptions!$B$24=2,C40*$B$42,C40),"")) | E40: =IF(ISNUMBER(B40),"Primary",IF(ISNUMBER(C40),IF(Assumptions!$B$24=2,"FOI scaled (fill)","FOI as reported (fill)"),"missing")) | F40: Primary 'ongoing data collection'; FOI fills, provisional (partial year)
A42: Primary ÷ FOI, overlapping years 2024–2025 (ratio of sums) | B42: =(B38+B39)/(C38+C39)

Sheet Salt_Beds
A1: Estimated number of salt beds per municipality
A2: N = annual production ÷ x. Alaminos City is the surveyed count (observed), all others are estimates.
A4: x used (kg/bed/yr) | B4: =Assumptions!B7
A5: x 2025 | B5: =Alaminos_Beds!B9
A6: x 2026 (provisional) | B6: =Alaminos_Beds!B10
A7: x legacy (handwritten) | B7: =Alaminos_Beds!B12
A8: Average bed area (m²) | B8: =Alaminos_Beds!B6
A11: Municipality | B11: Annual production used 2025 (kg) | C11: Source | D11: Estimated salt beds 2025 (base) | E11: Low (x = higher of 2025/2026) | F11: High (x = lower of 2025/2026) | G11: Beds if legacy x = 310.61 | H11: Beds implied by 2024 production | I11: Reported production area (ha) | J11: Implied bed area (ha) | K11: Implied ÷ reported | L11: Area-based bed count | M11: Area check | N11: Confidence
A12: Alaminos City | B12: =Annual_Production!M4 | C12: =Annual_Production!J4 | D12: =Alaminos_Beds!B4 | E12: =Alaminos_Beds!B4 | F12: =Alaminos_Beds!B4 | G12: =Assumptions!B9 | H12: =Annual_Production!L4/$B$4 | I12: =Alaminos_Beds!B5 | J12: =D12*$B$8/10000 | K12: =J12/I12 | L12: =I12*10000/$B$8 | M12: =IF(K12<=1.05,"Consistent","Exceeds reported area") | N12: High: beds observed; output primary, within 3% of FOI
A13: Anda | B13: =Annual_Production!M5 | C13: =Annual_Production!J5 | D13: =B13/$B$4 | E13: =B13/MAX($B$5,$B$6) | F13: =B13/MIN($B$5,$B$6) | G13: =B13/$B$7 | H13: =Annual_Production!L5/$B$4 | I13: n/a | J13: =D13*$B$8/10000 | K13: n/a | L13: n/a | M13: n/a | N13: Low–Medium: FOI only, coverage unverified
A14: Bani | B14: =Annual_Production!M6 | C14: =Annual_Production!J6 | D14: =B14/$B$4 | E14: =B14/MAX($B$5,$B$6) | F14: =B14/MIN($B$5,$B$6) | G14: =B14/$B$7 | H14: =Annual_Production!L6/$B$4 | I14: =Annual_Production!B24 | J14: =D14*$B$8/10000 | K14: =J14/I14 | L14: =I14*10000/$B$8 | M14: =IF(K14<=1.05,"Consistent","Exceeds reported area") | N14: Low–Medium: FOI basis; master sheet reports ~13× more (selector B11)
A15: Bolinao | B15: =Annual_Production!M7 | C15: =Annual_Production!J7 | D15: =B15/$B$4 | E15: =B15/MAX($B$5,$B$6) | F15: =B15/MIN($B$5,$B$6) | G15: =B15/$B$7 | H15: =Annual_Production!L7/$B$4 | I15: n/a | J15: =D15*$B$8/10000 | K15: n/a | L15: n/a | M15: n/a | N15: Low–Medium: FOI only, coverage unverified
A16: Dasol | B16: =Annual_Production!M8 | C16: =Annual_Production!J8 | D16: =B16/$B$4 | E16: =B16/MAX($B$5,$B$6) | F16: =B16/MIN($B$5,$B$6) | G16: =B16/$B$7 | H16: =Annual_Production!L8/$B$4 | I16: n/a | J16: =D16*$B$8/10000 | K16: n/a | L16: n/a | M16: n/a | N16: Low: FOI ≈ 3% of OPAg 2021; larger banigan reported
A17: Infanta | B17: =Annual_Production!M9 | C17: =Annual_Production!J9 | D17: =B17/$B$4 | E17: =B17/MAX($B$5,$B$6) | F17: =B17/MIN($B$5,$B$6) | G17: =B17/$B$7 | H17: =Annual_Production!L9/$B$4 | I17: n/a | J17: =D17*$B$8/10000 | K17: n/a | L17: n/a | M17: n/a | N17: Low–Medium: FOI only
A18: San Fabian | B18: =Annual_Production!M10 | C18: =Annual_Production!J10 | D18: =B18/$B$4 | E18: =B18/MAX($B$5,$B$6) | F18: =B18/MIN($B$5,$B$6) | G18: =B18/$B$7 | H18: =Annual_Production!L10/$B$4 | I18: =Annual_Production!C31 | J18: =D18*$B$8/10000 | K18: =J18/I18 | L18: =I18*10000/$B$8 | M18: n/a – cooked salt is not area-bound | N18: Annual: High · bed count: Low (cooked salt, 'bed-equivalent')
A19: Total | B19: =SUM(B12:B18) | D19: =SUM(D12:D18) | E19: =SUM(E12:E18) | F19: =SUM(F12:F18) | G19: =SUM(G12:G18) | H19: =SUM(H12:H18) | J19: =SUM(J12:J18)
A21: San Fabian beds are 'bed-equivalents': cooked (brine-boiling) salt is not area-bound, and 734 solar-size beds would need ≈2.6 ha against 0.06 ha reported. Use the area-based count (≈17) only if a literal bed count is needed.
A22: Bani on the FOI basis implies only ≈7% of its reported 204 ha as bed surface; on the primary basis (Assumptions!B11 = 2) it implies ≈98%, but that output is itself 40 t/ha × area (circular).
A23: Column H applies x to 2024 production; for Alaminos it gives 3,092 vs 7,410 surveyed. FOI 2024 covers assisted associations only, so 2024 bed counts are under-estimates.
A24: Alaminos annual production from the primary master-sheet rates (Assumptions!B23 = 2) is within 3% of FOI, so x calibrated on FOI (144.36) and on primary (Assumptions!B26, 148.35) agree (Testing T10).

Sheet Seasonal_Profile
A1: Seasonal profile of provincial production
A2: Source: FOI RS3969 (2024, assisted associations only) and RS4760 (2025, assisted + non-assisted). 2023 has Jul–Dec only and is not used.
A3: Series | B3: Jan | C3: Feb | D3: Mar | E3: Apr | F3: May | G3: Jun | H3: Jul | I3: Aug | J3: Sep | K3: Oct | L3: Nov | M3: Dec | N3: Total
A4: Provincial monthly volume 2024 (kg) | B4: 222196 | C4: 42396 | D4: 392226 | E4: 579850 | F4: 700550 | G4: 255650 | H4: 28600 | I4: 28950 | J4: 29250 | K4: 25300 | L4: 25050 | M4: 24700 | N4: =SUM(B4:M4)
A5: Provincial monthly volume 2025 (kg) | B5: 24550 | C5: 62132 | D5: 536165 | E5: 3740899 | F5: 2853521 | G5: 1425330 | H5: 399657 | I5: 94240 | J5: 164851 | K5: 190790 | L5: 230615 | M5: 304453 | N5: =SUM(B5:M5)
A7: Monthly share of annual total
A8: Observed share 2024 | B8: =B4/$N4 | C8: =C4/$N4 | D8: =D4/$N4 | E8: =E4/$N4 | F8: =F4/$N4 | G8: =G4/$N4 | H8: =H4/$N4 | I8: =I4/$N4 | ... M8: =M4/$N4 | N8: =SUM(B8:M8)
A9: Observed share 2025 | B9: =B5/$N5 | C9: =C5/$N5 | D9: =D5/$N5 | E9: =E5/$N5 | F9: =F5/$N5 | G9: =G5/$N5 | H9: =H5/$N5 | I9: =I5/$N5 | ... M9: =M5/$N5 | N9: =SUM(B9:M9)
A10: Pooled share (mean of 2024 and 2025) | B10: =AVERAGE(B8,B9) | C10: =AVERAGE(C8,C9) | D10: =AVERAGE(D8,D9) | E10: =AVERAGE(E8,E9) | F10: =AVERAGE(F8,F9) | G10: =AVERAGE(G8,G9) | H10: =AVERAGE(H8,H9) | I10: =AVERAGE(I8,I9) | ... M10: =AVERAGE(M8,M9) | N10: =SUM(B10:M10)
A11: Linear arithmetic (a1 + (j−1)·d) | B11: =$B$14+0*$B$15 | C11: =$B$14+1*$B$15 | D11: =$B$14+2*$B$15 | E11: =$B$14+3*$B$15 | F11: =$B$14+4*$B$15 | G11: =$B$14+5*$B$15 | H11: =$B$14+6*$B$15 | I11: =$B$14+7*$B$15 | J11: =$B$14+8*$B$15 | K11: =$B$14+9*$B$15 | L11: =$B$14+10*$B$15 | M11: =$B$14+11*$B$15 | N11: =SUM(B11:M11)
A12: Uniform (1/12) | B12: =1/12 | C12: =1/12 | D12: =1/12 | E12: =1/12 | F12: =1/12 | G12: =1/12 | H12: =1/12 | I12: =1/12 | ... M12: =1/12 | N12: =SUM(B12:M12)
A14: a1 (first-month share) | B14: =Assumptions!B6
A15: d = (1 − 12·a1) ÷ 66 (common difference) | B15: =(1-12*B14)/66
A17: Reconciliation of monthly vs municipal totals
A18: Year | B18: Sum of monthly series (kg) | C18: Sum of municipal table (kg) | D18: Difference (kg) | E18: Difference (%)
A19: 2024 | B19: =N4 | C19: =Annual_Production!B11 | D19: =B19-C19 | E19: =D19/C19
A20: 2025 | B20: =N5 | C20: =Annual_Production!C11 | D20: =B20-C20 | E20: =D20/C20
A21: 2024: the monthly file says 'assisted only' yet exceeds the municipal table that says 'assisted and non-assisted' – the notes on the two FOI files appear swapped or inconsistent.

Sheet Shares
A1: Monthly share applied to each municipality-year
A2: Selected by Assumptions!B5. Windowed municipalities (flag = 1) split evenly across their primary-stated production months.
A3: Municipality | B3: Year | C3: Use window | D3: Jan | E3: Feb | F3: Mar | G3: Apr | H3: May | I3: Jun | J3: Jul | K3: Aug | L3: Sep | M3: Oct | N3: Nov | O3: Dec | P3: Sum
A4: Alaminos City | B4: 2024 | C4: =Assumptions!C13 | D4: =IF(SUM(Monthly_Override!$C4:$N4)>0,Monthly_Override!C4/SUM(Monthly_Override!$C4:$N4),IF(Assumptions!$B$5=3,Seasonal_Profile!B$11,IF($C4=1,IF(Assumptions!$B$10=2,Assumptions!D$13*IF(Assumptions!$B$5=1,Seasonal_Profile!B$8,Seasonal_Profile!B$10)/IF(Assumptions!$B$5=1,SUMPRODUCT(Assumptions!$D$13:$O$13,Seasonal_Profile!$B$8:$M$8),SUMPRODUCT(Assumptions!$D$13:$O$13,Seasonal_Profile!$B$10:$M$10)),Assumptions!D$13/SUM(Assumptions!$D$13:$O$13)),IF(Assumptions!$B$5=1,Seasonal_Profile!B$8,Seasonal_Profile!B$10)))) | E4: =IF(SUM(Monthly_Override!$C4:$N4)>0,Monthly_Override!D4/SUM(Monthly_Override!$C4:$N4),IF(Assumptions!$B$5=3,Seasonal_Profile!C$11,IF($C4=1,IF(Assumptions!$B$10=2,Assumptions!E$13*IF(Assumptions!$B$5=1,Seasonal_Profile!C$8,Seasonal_Profile!C$10)/IF(Assumptions!$B$5=1,SUMPRODUCT(Assumptions!$D$13:$O$13,Seasonal_Profile!$B$8:$M$8),SUMPRODUCT(Assumptions!$D$13:$O$13,Seasonal_Profile!$B$10:$M$10)),Assumptions!E$13/SUM(Assumptions!$D$13:$O$13)),IF(Assumptions!$B$5=1,Seasonal_Profile!C$8,Seasonal_Profile!C$10)))) | F4: =IF(SUM(Monthly_Override!$C4:$N4)>0,Monthly_Override!E4/SUM(Monthly_Override!$C4:$N4),IF(Assumptions!$B$5=3,Seasonal_Profile!D$11,IF($C4=1,IF(Assumptions!$B$10=2,Assumptions!F$13*IF(Assumptions!$B$5=1,Seasonal_Profile!D$8,Seasonal_Profile!D$10)/IF(Assumptions!$B$5=1,SUMPRODUCT(Assumptions!$D$13:$O$13,Seasonal_Profile!$B$8:$M$8),SUMPRODUCT(Assumptions!$D$13:$O$13,Seasonal_Profile!$B$10:$M$10)),Assumptions!F$13/SUM(Assumptions!$D$13:$O$13)),IF(Assumptions!$B$5=1,Seasonal_Profile!D$8,Seasonal_Profile!D$10)))) | G4: =IF(SUM(Monthly_Override!$C4:$N4)>0,Monthly_Override!F4/SUM(Monthly_Override!$C4:$N4),IF(Assumptions!$B$5=3,Seasonal_Profile!E$11,IF($C4=1,IF(Assumptions!$B$10=2,Assumptions!G$13*IF(Assumptions!$B$5=1,Seasonal_Profile!E$8,Seasonal_Profile!E$10)/IF(Assumptions!$B$5=1,SUMPRODUCT(Assumptions!$D$13:$O$13,Seasonal_Profile!$B$8:$M$8),SUMPRODUCT(Assumptions!$D$13:$O$13,Seasonal_Profile!$B$10:$M$10)),Assumptions!G$13/SUM(Assumptions!$D$13:$O$13)),IF(Assumptions!$B$5=1,Seasonal_Profile!E$8,Seasonal_Profile!E$10)))) | H4: =IF(SUM(Monthly_Override!$C4:$N4)>0,Monthly_Override!G4/SUM(Monthly_Override!$C4:$N4),IF(Assumptions!$B$5=3,Seasonal_Profile!F$11,IF($C4=1,IF(Assumptions!$B$10=2,Assumptions!H$13*IF(Assumptions!$B$5=1,Seasonal_Profile!F$8,Seasonal_Profile!F$10)/IF(Assumptions!$B$5=1,SUMPRODUCT(Assumptions!$D$13:$O$13,Seasonal_Profile!$B$8:$M$8),SUMPRODUCT(Assumptions!$D$13:$O$13,Seasonal_Profile!$B$10:$M$10)),Assumptions!H$13/SUM(Assumptions!$D$13:$O$13)),IF(Assumptions!$B$5=1,Seasonal_Profile!F$8,Seasonal_Profile!F$10)))) | I4: =IF(SUM(Monthly_Override!$C4:$N4)>0,Monthly_Override!H4/SUM(Monthly_Override!$C4:$N4),IF(Assumptions!$B$5=3,Seasonal_Profile!G$11,IF($C4=1,IF(Assumptions!$B$10=2,Assumptions!I$13*IF(Assumptions!$B$5=1,Seasonal_Profile!G$8,Seasonal_Profile!G$10)/IF(Assumptions!$B$5=1,SUMPRODUCT(Assumptions!$D$13:$O$13,Seasonal_Profile!$B$8:$M$8),SUMPRODUCT(Assumptions!$D$13:$O$13,Seasonal_Profile!$B$10:$M$10)),Assumptions!I$13/SUM(Assumptions!$D$13:$O$13)),IF(Assumptions!$B$5=1,Seasonal_Profile!G$8,Seasonal_Profile!G$10)))) | J4: =IF(SUM(Monthly_Override!$C4:$N4)>0,Monthly_Override!I4/SUM(Monthly_Override!$C4:$N4),IF(Assumptions!$B$5=3,Seasonal_Profile!H$11,IF($C4=1,IF(Assumptions!$B$10=2,Assumptions!J$13*IF(Assumptions!$B$5=1,Seasonal_Profile!H$8,Seasonal_Profile!H$10)/IF(Assumptions!$B$5=1,SUMPRODUCT(Assumptions!$D$13:$O$13,Seasonal_Profile!$B$8:$M$8),SUMPRODUCT(Assumptions!$D$13:$O$13,Seasonal_Profile!$B$10:$M$10)),Assumptions!J$13/SUM(Assumptions!$D$13:$O$13)),IF(Assumptions!$B$5=1,Seasonal_Profile!H$8,Seasonal_Profile!H$10)))) | K4: =IF(SUM(Monthly_Override!$C4:$N4)>0,Monthly_Override!J4/SUM(Monthly_Override!$C4:$N4),IF(Assumptions!$B$5=3,Seasonal_Profile!I$11,IF($C4=1,IF(Assumptions!$B$10=2,Assumptions!K$13*IF(Assumptions!$B$5=1,Seasonal_Profile!I$8,Seasonal_Profile!I$10)/IF(Assumptions!$B$5=1,SUMPRODUCT(Assumptions!$D$13:$O$13,Seasonal_Profile!$B$8:$M$8),SUMPRODUCT(Assumptions!$D$13:$O$13,Seasonal_Profile!$B$10:$M$10)),Assumptions!K$13/SUM(Assumptions!$D$13:$O$13)),IF(Assumptions!$B$5=1,Seasonal_Profile!I$8,Seasonal_Profile!I$10)))) | ... O4: =IF(SUM(Monthly_Override!$C4:$N4)>0,Monthly_Override!N4/SUM(Monthly_Override!$C4:$N4),IF(Assumptions!$B$5=3,Seasonal_Profile!M$11,IF($C4=1,IF(Assumptions!$B$10=2,Assumptions!O$13*IF(Assumptions!$B$5=1,Seasonal_Profile!M$8,Seasonal_Profile!M$10)/IF(Assumptions!$B$5=1,SUMPRODUCT(Assumptions!$D$13:$O$13,Seasonal_Profile!$B$8:$M$8),SUMPRODUCT(Assumptions!$D$13:$O$13,Seasonal_Profile!$B$10:$M$10)),Assumptions!O$13/SUM(Assumptions!$D$13:$O$13)),IF(Assumptions!$B$5=1,Seasonal_Profile!M$8,Seasonal_Profile!M$10)))) | P4: =SUM(D4:O4)
A5: Anda | B5: 2024 | C5: =Assumptions!C14 | D5: =IF(SUM(Monthly_Override!$C5:$N5)>0,Monthly_Override!C5/SUM(Monthly_Override!$C5:$N5),IF(Assumptions!$B$5=3,Seasonal_Profile!B$11,IF($C5=1,IF(Assumptions!$B$10=2,Assumptions!D$14*IF(Assumptions!$B$5=1,Seasonal_Profile!B$8,Seasonal_Profile!B$10)/IF(Assumptions!$B$5=1,SUMPRODUCT(Assumptions!$D$14:$O$14,Seasonal_Profile!$B$8:$M$8),SUMPRODUCT(Assumptions!$D$14:$O$14,Seasonal_Profile!$B$10:$M$10)),Assumptions!D$14/SUM(Assumptions!$D$14:$O$14)),IF(Assumptions!$B$5=1,Seasonal_Profile!B$8,Seasonal_Profile!B$10)))) | E5: =IF(SUM(Monthly_Override!$C5:$N5)>0,Monthly_Override!D5/SUM(Monthly_Override!$C5:$N5),IF(Assumptions!$B$5=3,Seasonal_Profile!C$11,IF($C5=1,IF(Assumptions!$B$10=2,Assumptions!E$14*IF(Assumptions!$B$5=1,Seasonal_Profile!C$8,Seasonal_Profile!C$10)/IF(Assumptions!$B$5=1,SUMPRODUCT(Assumptions!$D$14:$O$14,Seasonal_Profile!$B$8:$M$8),SUMPRODUCT(Assumptions!$D$14:$O$14,Seasonal_Profile!$B$10:$M$10)),Assumptions!E$14/SUM(Assumptions!$D$14:$O$14)),IF(Assumptions!$B$5=1,Seasonal_Profile!C$8,Seasonal_Profile!C$10)))) | F5: =IF(SUM(Monthly_Override!$C5:$N5)>0,Monthly_Override!E5/SUM(Monthly_Override!$C5:$N5),IF(Assumptions!$B$5=3,Seasonal_Profile!D$11,IF($C5=1,IF(Assumptions!$B$10=2,Assumptions!F$14*IF(Assumptions!$B$5=1,Seasonal_Profile!D$8,Seasonal_Profile!D$10)/IF(Assumptions!$B$5=1,SUMPRODUCT(Assumptions!$D$14:$O$14,Seasonal_Profile!$B$8:$M$8),SUMPRODUCT(Assumptions!$D$14:$O$14,Seasonal_Profile!$B$10:$M$10)),Assumptions!F$14/SUM(Assumptions!$D$14:$O$14)),IF(Assumptions!$B$5=1,Seasonal_Profile!D$8,Seasonal_Profile!D$10)))) | G5: =IF(SUM(Monthly_Override!$C5:$N5)>0,Monthly_Override!F5/SUM(Monthly_Override!$C5:$N5),IF(Assumptions!$B$5=3,Seasonal_Profile!E$11,IF($C5=1,IF(Assumptions!$B$10=2,Assumptions!G$14*IF(Assumptions!$B$5=1,Seasonal_Profile!E$8,Seasonal_Profile!E$10)/IF(Assumptions!$B$5=1,SUMPRODUCT(Assumptions!$D$14:$O$14,Seasonal_Profile!$B$8:$M$8),SUMPRODUCT(Assumptions!$D$14:$O$14,Seasonal_Profile!$B$10:$M$10)),Assumptions!G$14/SUM(Assumptions!$D$14:$O$14)),IF(Assumptions!$B$5=1,Seasonal_Profile!E$8,Seasonal_Profile!E$10)))) | H5: =IF(SUM(Monthly_Override!$C5:$N5)>0,Monthly_Override!G5/SUM(Monthly_Override!$C5:$N5),IF(Assumptions!$B$5=3,Seasonal_Profile!F$11,IF($C5=1,IF(Assumptions!$B$10=2,Assumptions!H$14*IF(Assumptions!$B$5=1,Seasonal_Profile!F$8,Seasonal_Profile!F$10)/IF(Assumptions!$B$5=1,SUMPRODUCT(Assumptions!$D$14:$O$14,Seasonal_Profile!$B$8:$M$8),SUMPRODUCT(Assumptions!$D$14:$O$14,Seasonal_Profile!$B$10:$M$10)),Assumptions!H$14/SUM(Assumptions!$D$14:$O$14)),IF(Assumptions!$B$5=1,Seasonal_Profile!F$8,Seasonal_Profile!F$10)))) | I5: =IF(SUM(Monthly_Override!$C5:$N5)>0,Monthly_Override!H5/SUM(Monthly_Override!$C5:$N5),IF(Assumptions!$B$5=3,Seasonal_Profile!G$11,IF($C5=1,IF(Assumptions!$B$10=2,Assumptions!I$14*IF(Assumptions!$B$5=1,Seasonal_Profile!G$8,Seasonal_Profile!G$10)/IF(Assumptions!$B$5=1,SUMPRODUCT(Assumptions!$D$14:$O$14,Seasonal_Profile!$B$8:$M$8),SUMPRODUCT(Assumptions!$D$14:$O$14,Seasonal_Profile!$B$10:$M$10)),Assumptions!I$14/SUM(Assumptions!$D$14:$O$14)),IF(Assumptions!$B$5=1,Seasonal_Profile!G$8,Seasonal_Profile!G$10)))) | J5: =IF(SUM(Monthly_Override!$C5:$N5)>0,Monthly_Override!I5/SUM(Monthly_Override!$C5:$N5),IF(Assumptions!$B$5=3,Seasonal_Profile!H$11,IF($C5=1,IF(Assumptions!$B$10=2,Assumptions!J$14*IF(Assumptions!$B$5=1,Seasonal_Profile!H$8,Seasonal_Profile!H$10)/IF(Assumptions!$B$5=1,SUMPRODUCT(Assumptions!$D$14:$O$14,Seasonal_Profile!$B$8:$M$8),SUMPRODUCT(Assumptions!$D$14:$O$14,Seasonal_Profile!$B$10:$M$10)),Assumptions!J$14/SUM(Assumptions!$D$14:$O$14)),IF(Assumptions!$B$5=1,Seasonal_Profile!H$8,Seasonal_Profile!H$10)))) | K5: =IF(SUM(Monthly_Override!$C5:$N5)>0,Monthly_Override!J5/SUM(Monthly_Override!$C5:$N5),IF(Assumptions!$B$5=3,Seasonal_Profile!I$11,IF($C5=1,IF(Assumptions!$B$10=2,Assumptions!K$14*IF(Assumptions!$B$5=1,Seasonal_Profile!I$8,Seasonal_Profile!I$10)/IF(Assumptions!$B$5=1,SUMPRODUCT(Assumptions!$D$14:$O$14,Seasonal_Profile!$B$8:$M$8),SUMPRODUCT(Assumptions!$D$14:$O$14,Seasonal_Profile!$B$10:$M$10)),Assumptions!K$14/SUM(Assumptions!$D$14:$O$14)),IF(Assumptions!$B$5=1,Seasonal_Profile!I$8,Seasonal_Profile!I$10)))) | ... O5: =IF(SUM(Monthly_Override!$C5:$N5)>0,Monthly_Override!N5/SUM(Monthly_Override!$C5:$N5),IF(Assumptions!$B$5=3,Seasonal_Profile!M$11,IF($C5=1,IF(Assumptions!$B$10=2,Assumptions!O$14*IF(Assumptions!$B$5=1,Seasonal_Profile!M$8,Seasonal_Profile!M$10)/IF(Assumptions!$B$5=1,SUMPRODUCT(Assumptions!$D$14:$O$14,Seasonal_Profile!$B$8:$M$8),SUMPRODUCT(Assumptions!$D$14:$O$14,Seasonal_Profile!$B$10:$M$10)),Assumptions!O$14/SUM(Assumptions!$D$14:$O$14)),IF(Assumptions!$B$5=1,Seasonal_Profile!M$8,Seasonal_Profile!M$10)))) | P5: =SUM(D5:O5)
A6: Bani | B6: 2024 | C6: =Assumptions!C15 | D6: =IF(SUM(Monthly_Override!$C6:$N6)>0,Monthly_Override!C6/SUM(Monthly_Override!$C6:$N6),IF(Assumptions!$B$5=3,Seasonal_Profile!B$11,IF($C6=1,IF(Assumptions!$B$10=2,Assumptions!D$15*IF(Assumptions!$B$5=1,Seasonal_Profile!B$8,Seasonal_Profile!B$10)/IF(Assumptions!$B$5=1,SUMPRODUCT(Assumptions!$D$15:$O$15,Seasonal_Profile!$B$8:$M$8),SUMPRODUCT(Assumptions!$D$15:$O$15,Seasonal_Profile!$B$10:$M$10)),Assumptions!D$15/SUM(Assumptions!$D$15:$O$15)),IF(Assumptions!$B$5=1,Seasonal_Profile!B$8,Seasonal_Profile!B$10)))) | E6: =IF(SUM(Monthly_Override!$C6:$N6)>0,Monthly_Override!D6/SUM(Monthly_Override!$C6:$N6),IF(Assumptions!$B$5=3,Seasonal_Profile!C$11,IF($C6=1,IF(Assumptions!$B$10=2,Assumptions!E$15*IF(Assumptions!$B$5=1,Seasonal_Profile!C$8,Seasonal_Profile!C$10)/IF(Assumptions!$B$5=1,SUMPRODUCT(Assumptions!$D$15:$O$15,Seasonal_Profile!$B$8:$M$8),SUMPRODUCT(Assumptions!$D$15:$O$15,Seasonal_Profile!$B$10:$M$10)),Assumptions!E$15/SUM(Assumptions!$D$15:$O$15)),IF(Assumptions!$B$5=1,Seasonal_Profile!C$8,Seasonal_Profile!C$10)))) | F6: =IF(SUM(Monthly_Override!$C6:$N6)>0,Monthly_Override!E6/SUM(Monthly_Override!$C6:$N6),IF(Assumptions!$B$5=3,Seasonal_Profile!D$11,IF($C6=1,IF(Assumptions!$B$10=2,Assumptions!F$15*IF(Assumptions!$B$5=1,Seasonal_Profile!D$8,Seasonal_Profile!D$10)/IF(Assumptions!$B$5=1,SUMPRODUCT(Assumptions!$D$15:$O$15,Seasonal_Profile!$B$8:$M$8),SUMPRODUCT(Assumptions!$D$15:$O$15,Seasonal_Profile!$B$10:$M$10)),Assumptions!F$15/SUM(Assumptions!$D$15:$O$15)),IF(Assumptions!$B$5=1,Seasonal_Profile!D$8,Seasonal_Profile!D$10)))) | G6: =IF(SUM(Monthly_Override!$C6:$N6)>0,Monthly_Override!F6/SUM(Monthly_Override!$C6:$N6),IF(Assumptions!$B$5=3,Seasonal_Profile!E$11,IF($C6=1,IF(Assumptions!$B$10=2,Assumptions!G$15*IF(Assumptions!$B$5=1,Seasonal_Profile!E$8,Seasonal_Profile!E$10)/IF(Assumptions!$B$5=1,SUMPRODUCT(Assumptions!$D$15:$O$15,Seasonal_Profile!$B$8:$M$8),SUMPRODUCT(Assumptions!$D$15:$O$15,Seasonal_Profile!$B$10:$M$10)),Assumptions!G$15/SUM(Assumptions!$D$15:$O$15)),IF(Assumptions!$B$5=1,Seasonal_Profile!E$8,Seasonal_Profile!E$10)))) | H6: =IF(SUM(Monthly_Override!$C6:$N6)>0,Monthly_Override!G6/SUM(Monthly_Override!$C6:$N6),IF(Assumptions!$B$5=3,Seasonal_Profile!F$11,IF($C6=1,IF(Assumptions!$B$10=2,Assumptions!H$15*IF(Assumptions!$B$5=1,Seasonal_Profile!F$8,Seasonal_Profile!F$10)/IF(Assumptions!$B$5=1,SUMPRODUCT(Assumptions!$D$15:$O$15,Seasonal_Profile!$B$8:$M$8),SUMPRODUCT(Assumptions!$D$15:$O$15,Seasonal_Profile!$B$10:$M$10)),Assumptions!H$15/SUM(Assumptions!$D$15:$O$15)),IF(Assumptions!$B$5=1,Seasonal_Profile!F$8,Seasonal_Profile!F$10)))) | I6: =IF(SUM(Monthly_Override!$C6:$N6)>0,Monthly_Override!H6/SUM(Monthly_Override!$C6:$N6),IF(Assumptions!$B$5=3,Seasonal_Profile!G$11,IF($C6=1,IF(Assumptions!$B$10=2,Assumptions!I$15*IF(Assumptions!$B$5=1,Seasonal_Profile!G$8,Seasonal_Profile!G$10)/IF(Assumptions!$B$5=1,SUMPRODUCT(Assumptions!$D$15:$O$15,Seasonal_Profile!$B$8:$M$8),SUMPRODUCT(Assumptions!$D$15:$O$15,Seasonal_Profile!$B$10:$M$10)),Assumptions!I$15/SUM(Assumptions!$D$15:$O$15)),IF(Assumptions!$B$5=1,Seasonal_Profile!G$8,Seasonal_Profile!G$10)))) | J6: =IF(SUM(Monthly_Override!$C6:$N6)>0,Monthly_Override!I6/SUM(Monthly_Override!$C6:$N6),IF(Assumptions!$B$5=3,Seasonal_Profile!H$11,IF($C6=1,IF(Assumptions!$B$10=2,Assumptions!J$15*IF(Assumptions!$B$5=1,Seasonal_Profile!H$8,Seasonal_Profile!H$10)/IF(Assumptions!$B$5=1,SUMPRODUCT(Assumptions!$D$15:$O$15,Seasonal_Profile!$B$8:$M$8),SUMPRODUCT(Assumptions!$D$15:$O$15,Seasonal_Profile!$B$10:$M$10)),Assumptions!J$15/SUM(Assumptions!$D$15:$O$15)),IF(Assumptions!$B$5=1,Seasonal_Profile!H$8,Seasonal_Profile!H$10)))) | K6: =IF(SUM(Monthly_Override!$C6:$N6)>0,Monthly_Override!J6/SUM(Monthly_Override!$C6:$N6),IF(Assumptions!$B$5=3,Seasonal_Profile!I$11,IF($C6=1,IF(Assumptions!$B$10=2,Assumptions!K$15*IF(Assumptions!$B$5=1,Seasonal_Profile!I$8,Seasonal_Profile!I$10)/IF(Assumptions!$B$5=1,SUMPRODUCT(Assumptions!$D$15:$O$15,Seasonal_Profile!$B$8:$M$8),SUMPRODUCT(Assumptions!$D$15:$O$15,Seasonal_Profile!$B$10:$M$10)),Assumptions!K$15/SUM(Assumptions!$D$15:$O$15)),IF(Assumptions!$B$5=1,Seasonal_Profile!I$8,Seasonal_Profile!I$10)))) | ... O6: =IF(SUM(Monthly_Override!$C6:$N6)>0,Monthly_Override!N6/SUM(Monthly_Override!$C6:$N6),IF(Assumptions!$B$5=3,Seasonal_Profile!M$11,IF($C6=1,IF(Assumptions!$B$10=2,Assumptions!O$15*IF(Assumptions!$B$5=1,Seasonal_Profile!M$8,Seasonal_Profile!M$10)/IF(Assumptions!$B$5=1,SUMPRODUCT(Assumptions!$D$15:$O$15,Seasonal_Profile!$B$8:$M$8),SUMPRODUCT(Assumptions!$D$15:$O$15,Seasonal_Profile!$B$10:$M$10)),Assumptions!O$15/SUM(Assumptions!$D$15:$O$15)),IF(Assumptions!$B$5=1,Seasonal_Profile!M$8,Seasonal_Profile!M$10)))) | P6: =SUM(D6:O6)
A7: Bolinao | B7: 2024 | C7: =Assumptions!C16 | D7: =IF(SUM(Monthly_Override!$C7:$N7)>0,Monthly_Override!C7/SUM(Monthly_Override!$C7:$N7),IF(Assumptions!$B$5=3,Seasonal_Profile!B$11,IF($C7=1,IF(Assumptions!$B$10=2,Assumptions!D$16*IF(Assumptions!$B$5=1,Seasonal_Profile!B$8,Seasonal_Profile!B$10)/IF(Assumptions!$B$5=1,SUMPRODUCT(Assumptions!$D$16:$O$16,Seasonal_Profile!$B$8:$M$8),SUMPRODUCT(Assumptions!$D$16:$O$16,Seasonal_Profile!$B$10:$M$10)),Assumptions!D$16/SUM(Assumptions!$D$16:$O$16)),IF(Assumptions!$B$5=1,Seasonal_Profile!B$8,Seasonal_Profile!B$10)))) | E7: =IF(SUM(Monthly_Override!$C7:$N7)>0,Monthly_Override!D7/SUM(Monthly_Override!$C7:$N7),IF(Assumptions!$B$5=3,Seasonal_Profile!C$11,IF($C7=1,IF(Assumptions!$B$10=2,Assumptions!E$16*IF(Assumptions!$B$5=1,Seasonal_Profile!C$8,Seasonal_Profile!C$10)/IF(Assumptions!$B$5=1,SUMPRODUCT(Assumptions!$D$16:$O$16,Seasonal_Profile!$B$8:$M$8),SUMPRODUCT(Assumptions!$D$16:$O$16,Seasonal_Profile!$B$10:$M$10)),Assumptions!E$16/SUM(Assumptions!$D$16:$O$16)),IF(Assumptions!$B$5=1,Seasonal_Profile!C$8,Seasonal_Profile!C$10)))) | F7: =IF(SUM(Monthly_Override!$C7:$N7)>0,Monthly_Override!E7/SUM(Monthly_Override!$C7:$N7),IF(Assumptions!$B$5=3,Seasonal_Profile!D$11,IF($C7=1,IF(Assumptions!$B$10=2,Assumptions!F$16*IF(Assumptions!$B$5=1,Seasonal_Profile!D$8,Seasonal_Profile!D$10)/IF(Assumptions!$B$5=1,SUMPRODUCT(Assumptions!$D$16:$O$16,Seasonal_Profile!$B$8:$M$8),SUMPRODUCT(Assumptions!$D$16:$O$16,Seasonal_Profile!$B$10:$M$10)),Assumptions!F$16/SUM(Assumptions!$D$16:$O$16)),IF(Assumptions!$B$5=1,Seasonal_Profile!D$8,Seasonal_Profile!D$10)))) | G7: =IF(SUM(Monthly_Override!$C7:$N7)>0,Monthly_Override!F7/SUM(Monthly_Override!$C7:$N7),IF(Assumptions!$B$5=3,Seasonal_Profile!E$11,IF($C7=1,IF(Assumptions!$B$10=2,Assumptions!G$16*IF(Assumptions!$B$5=1,Seasonal_Profile!E$8,Seasonal_Profile!E$10)/IF(Assumptions!$B$5=1,SUMPRODUCT(Assumptions!$D$16:$O$16,Seasonal_Profile!$B$8:$M$8),SUMPRODUCT(Assumptions!$D$16:$O$16,Seasonal_Profile!$B$10:$M$10)),Assumptions!G$16/SUM(Assumptions!$D$16:$O$16)),IF(Assumptions!$B$5=1,Seasonal_Profile!E$8,Seasonal_Profile!E$10)))) | H7: =IF(SUM(Monthly_Override!$C7:$N7)>0,Monthly_Override!G7/SUM(Monthly_Override!$C7:$N7),IF(Assumptions!$B$5=3,Seasonal_Profile!F$11,IF($C7=1,IF(Assumptions!$B$10=2,Assumptions!H$16*IF(Assumptions!$B$5=1,Seasonal_Profile!F$8,Seasonal_Profile!F$10)/IF(Assumptions!$B$5=1,SUMPRODUCT(Assumptions!$D$16:$O$16,Seasonal_Profile!$B$8:$M$8),SUMPRODUCT(Assumptions!$D$16:$O$16,Seasonal_Profile!$B$10:$M$10)),Assumptions!H$16/SUM(Assumptions!$D$16:$O$16)),IF(Assumptions!$B$5=1,Seasonal_Profile!F$8,Seasonal_Profile!F$10)))) | I7: =IF(SUM(Monthly_Override!$C7:$N7)>0,Monthly_Override!H7/SUM(Monthly_Override!$C7:$N7),IF(Assumptions!$B$5=3,Seasonal_Profile!G$11,IF($C7=1,IF(Assumptions!$B$10=2,Assumptions!I$16*IF(Assumptions!$B$5=1,Seasonal_Profile!G$8,Seasonal_Profile!G$10)/IF(Assumptions!$B$5=1,SUMPRODUCT(Assumptions!$D$16:$O$16,Seasonal_Profile!$B$8:$M$8),SUMPRODUCT(Assumptions!$D$16:$O$16,Seasonal_Profile!$B$10:$M$10)),Assumptions!I$16/SUM(Assumptions!$D$16:$O$16)),IF(Assumptions!$B$5=1,Seasonal_Profile!G$8,Seasonal_Profile!G$10)))) | J7: =IF(SUM(Monthly_Override!$C7:$N7)>0,Monthly_Override!I7/SUM(Monthly_Override!$C7:$N7),IF(Assumptions!$B$5=3,Seasonal_Profile!H$11,IF($C7=1,IF(Assumptions!$B$10=2,Assumptions!J$16*IF(Assumptions!$B$5=1,Seasonal_Profile!H$8,Seasonal_Profile!H$10)/IF(Assumptions!$B$5=1,SUMPRODUCT(Assumptions!$D$16:$O$16,Seasonal_Profile!$B$8:$M$8),SUMPRODUCT(Assumptions!$D$16:$O$16,Seasonal_Profile!$B$10:$M$10)),Assumptions!J$16/SUM(Assumptions!$D$16:$O$16)),IF(Assumptions!$B$5=1,Seasonal_Profile!H$8,Seasonal_Profile!H$10)))) | K7: =IF(SUM(Monthly_Override!$C7:$N7)>0,Monthly_Override!J7/SUM(Monthly_Override!$C7:$N7),IF(Assumptions!$B$5=3,Seasonal_Profile!I$11,IF($C7=1,IF(Assumptions!$B$10=2,Assumptions!K$16*IF(Assumptions!$B$5=1,Seasonal_Profile!I$8,Seasonal_Profile!I$10)/IF(Assumptions!$B$5=1,SUMPRODUCT(Assumptions!$D$16:$O$16,Seasonal_Profile!$B$8:$M$8),SUMPRODUCT(Assumptions!$D$16:$O$16,Seasonal_Profile!$B$10:$M$10)),Assumptions!K$16/SUM(Assumptions!$D$16:$O$16)),IF(Assumptions!$B$5=1,Seasonal_Profile!I$8,Seasonal_Profile!I$10)))) | ... O7: =IF(SUM(Monthly_Override!$C7:$N7)>0,Monthly_Override!N7/SUM(Monthly_Override!$C7:$N7),IF(Assumptions!$B$5=3,Seasonal_Profile!M$11,IF($C7=1,IF(Assumptions!$B$10=2,Assumptions!O$16*IF(Assumptions!$B$5=1,Seasonal_Profile!M$8,Seasonal_Profile!M$10)/IF(Assumptions!$B$5=1,SUMPRODUCT(Assumptions!$D$16:$O$16,Seasonal_Profile!$B$8:$M$8),SUMPRODUCT(Assumptions!$D$16:$O$16,Seasonal_Profile!$B$10:$M$10)),Assumptions!O$16/SUM(Assumptions!$D$16:$O$16)),IF(Assumptions!$B$5=1,Seasonal_Profile!M$8,Seasonal_Profile!M$10)))) | P7: =SUM(D7:O7)
A8: Dasol | B8: 2024 | C8: =Assumptions!C17 | D8: =IF(SUM(Monthly_Override!$C8:$N8)>0,Monthly_Override!C8/SUM(Monthly_Override!$C8:$N8),IF(Assumptions!$B$5=3,Seasonal_Profile!B$11,IF($C8=1,IF(Assumptions!$B$10=2,Assumptions!D$17*IF(Assumptions!$B$5=1,Seasonal_Profile!B$8,Seasonal_Profile!B$10)/IF(Assumptions!$B$5=1,SUMPRODUCT(Assumptions!$D$17:$O$17,Seasonal_Profile!$B$8:$M$8),SUMPRODUCT(Assumptions!$D$17:$O$17,Seasonal_Profile!$B$10:$M$10)),Assumptions!D$17/SUM(Assumptions!$D$17:$O$17)),IF(Assumptions!$B$5=1,Seasonal_Profile!B$8,Seasonal_Profile!B$10)))) | E8: =IF(SUM(Monthly_Override!$C8:$N8)>0,Monthly_Override!D8/SUM(Monthly_Override!$C8:$N8),IF(Assumptions!$B$5=3,Seasonal_Profile!C$11,IF($C8=1,IF(Assumptions!$B$10=2,Assumptions!E$17*IF(Assumptions!$B$5=1,Seasonal_Profile!C$8,Seasonal_Profile!C$10)/IF(Assumptions!$B$5=1,SUMPRODUCT(Assumptions!$D$17:$O$17,Seasonal_Profile!$B$8:$M$8),SUMPRODUCT(Assumptions!$D$17:$O$17,Seasonal_Profile!$B$10:$M$10)),Assumptions!E$17/SUM(Assumptions!$D$17:$O$17)),IF(Assumptions!$B$5=1,Seasonal_Profile!C$8,Seasonal_Profile!C$10)))) | F8: =IF(SUM(Monthly_Override!$C8:$N8)>0,Monthly_Override!E8/SUM(Monthly_Override!$C8:$N8),IF(Assumptions!$B$5=3,Seasonal_Profile!D$11,IF($C8=1,IF(Assumptions!$B$10=2,Assumptions!F$17*IF(Assumptions!$B$5=1,Seasonal_Profile!D$8,Seasonal_Profile!D$10)/IF(Assumptions!$B$5=1,SUMPRODUCT(Assumptions!$D$17:$O$17,Seasonal_Profile!$B$8:$M$8),SUMPRODUCT(Assumptions!$D$17:$O$17,Seasonal_Profile!$B$10:$M$10)),Assumptions!F$17/SUM(Assumptions!$D$17:$O$17)),IF(Assumptions!$B$5=1,Seasonal_Profile!D$8,Seasonal_Profile!D$10)))) | G8: =IF(SUM(Monthly_Override!$C8:$N8)>0,Monthly_Override!F8/SUM(Monthly_Override!$C8:$N8),IF(Assumptions!$B$5=3,Seasonal_Profile!E$11,IF($C8=1,IF(Assumptions!$B$10=2,Assumptions!G$17*IF(Assumptions!$B$5=1,Seasonal_Profile!E$8,Seasonal_Profile!E$10)/IF(Assumptions!$B$5=1,SUMPRODUCT(Assumptions!$D$17:$O$17,Seasonal_Profile!$B$8:$M$8),SUMPRODUCT(Assumptions!$D$17:$O$17,Seasonal_Profile!$B$10:$M$10)),Assumptions!G$17/SUM(Assumptions!$D$17:$O$17)),IF(Assumptions!$B$5=1,Seasonal_Profile!E$8,Seasonal_Profile!E$10)))) | H8: =IF(SUM(Monthly_Override!$C8:$N8)>0,Monthly_Override!G8/SUM(Monthly_Override!$C8:$N8),IF(Assumptions!$B$5=3,Seasonal_Profile!F$11,IF($C8=1,IF(Assumptions!$B$10=2,Assumptions!H$17*IF(Assumptions!$B$5=1,Seasonal_Profile!F$8,Seasonal_Profile!F$10)/IF(Assumptions!$B$5=1,SUMPRODUCT(Assumptions!$D$17:$O$17,Seasonal_Profile!$B$8:$M$8),SUMPRODUCT(Assumptions!$D$17:$O$17,Seasonal_Profile!$B$10:$M$10)),Assumptions!H$17/SUM(Assumptions!$D$17:$O$17)),IF(Assumptions!$B$5=1,Seasonal_Profile!F$8,Seasonal_Profile!F$10)))) | I8: =IF(SUM(Monthly_Override!$C8:$N8)>0,Monthly_Override!H8/SUM(Monthly_Override!$C8:$N8),IF(Assumptions!$B$5=3,Seasonal_Profile!G$11,IF($C8=1,IF(Assumptions!$B$10=2,Assumptions!I$17*IF(Assumptions!$B$5=1,Seasonal_Profile!G$8,Seasonal_Profile!G$10)/IF(Assumptions!$B$5=1,SUMPRODUCT(Assumptions!$D$17:$O$17,Seasonal_Profile!$B$8:$M$8),SUMPRODUCT(Assumptions!$D$17:$O$17,Seasonal_Profile!$B$10:$M$10)),Assumptions!I$17/SUM(Assumptions!$D$17:$O$17)),IF(Assumptions!$B$5=1,Seasonal_Profile!G$8,Seasonal_Profile!G$10)))) | J8: =IF(SUM(Monthly_Override!$C8:$N8)>0,Monthly_Override!I8/SUM(Monthly_Override!$C8:$N8),IF(Assumptions!$B$5=3,Seasonal_Profile!H$11,IF($C8=1,IF(Assumptions!$B$10=2,Assumptions!J$17*IF(Assumptions!$B$5=1,Seasonal_Profile!H$8,Seasonal_Profile!H$10)/IF(Assumptions!$B$5=1,SUMPRODUCT(Assumptions!$D$17:$O$17,Seasonal_Profile!$B$8:$M$8),SUMPRODUCT(Assumptions!$D$17:$O$17,Seasonal_Profile!$B$10:$M$10)),Assumptions!J$17/SUM(Assumptions!$D$17:$O$17)),IF(Assumptions!$B$5=1,Seasonal_Profile!H$8,Seasonal_Profile!H$10)))) | K8: =IF(SUM(Monthly_Override!$C8:$N8)>0,Monthly_Override!J8/SUM(Monthly_Override!$C8:$N8),IF(Assumptions!$B$5=3,Seasonal_Profile!I$11,IF($C8=1,IF(Assumptions!$B$10=2,Assumptions!K$17*IF(Assumptions!$B$5=1,Seasonal_Profile!I$8,Seasonal_Profile!I$10)/IF(Assumptions!$B$5=1,SUMPRODUCT(Assumptions!$D$17:$O$17,Seasonal_Profile!$B$8:$M$8),SUMPRODUCT(Assumptions!$D$17:$O$17,Seasonal_Profile!$B$10:$M$10)),Assumptions!K$17/SUM(Assumptions!$D$17:$O$17)),IF(Assumptions!$B$5=1,Seasonal_Profile!I$8,Seasonal_Profile!I$10)))) | ... O8: =IF(SUM(Monthly_Override!$C8:$N8)>0,Monthly_Override!N8/SUM(Monthly_Override!$C8:$N8),IF(Assumptions!$B$5=3,Seasonal_Profile!M$11,IF($C8=1,IF(Assumptions!$B$10=2,Assumptions!O$17*IF(Assumptions!$B$5=1,Seasonal_Profile!M$8,Seasonal_Profile!M$10)/IF(Assumptions!$B$5=1,SUMPRODUCT(Assumptions!$D$17:$O$17,Seasonal_Profile!$B$8:$M$8),SUMPRODUCT(Assumptions!$D$17:$O$17,Seasonal_Profile!$B$10:$M$10)),Assumptions!O$17/SUM(Assumptions!$D$17:$O$17)),IF(Assumptions!$B$5=1,Seasonal_Profile!M$8,Seasonal_Profile!M$10)))) | P8: =SUM(D8:O8)
A9: Infanta | B9: 2024 | C9: =Assumptions!C18 | D9: =IF(SUM(Monthly_Override!$C9:$N9)>0,Monthly_Override!C9/SUM(Monthly_Override!$C9:$N9),IF(Assumptions!$B$5=3,Seasonal_Profile!B$11,IF($C9=1,IF(Assumptions!$B$10=2,Assumptions!D$18*IF(Assumptions!$B$5=1,Seasonal_Profile!B$8,Seasonal_Profile!B$10)/IF(Assumptions!$B$5=1,SUMPRODUCT(Assumptions!$D$18:$O$18,Seasonal_Profile!$B$8:$M$8),SUMPRODUCT(Assumptions!$D$18:$O$18,Seasonal_Profile!$B$10:$M$10)),Assumptions!D$18/SUM(Assumptions!$D$18:$O$18)),IF(Assumptions!$B$5=1,Seasonal_Profile!B$8,Seasonal_Profile!B$10)))) | E9: =IF(SUM(Monthly_Override!$C9:$N9)>0,Monthly_Override!D9/SUM(Monthly_Override!$C9:$N9),IF(Assumptions!$B$5=3,Seasonal_Profile!C$11,IF($C9=1,IF(Assumptions!$B$10=2,Assumptions!E$18*IF(Assumptions!$B$5=1,Seasonal_Profile!C$8,Seasonal_Profile!C$10)/IF(Assumptions!$B$5=1,SUMPRODUCT(Assumptions!$D$18:$O$18,Seasonal_Profile!$B$8:$M$8),SUMPRODUCT(Assumptions!$D$18:$O$18,Seasonal_Profile!$B$10:$M$10)),Assumptions!E$18/SUM(Assumptions!$D$18:$O$18)),IF(Assumptions!$B$5=1,Seasonal_Profile!C$8,Seasonal_Profile!C$10)))) | F9: =IF(SUM(Monthly_Override!$C9:$N9)>0,Monthly_Override!E9/SUM(Monthly_Override!$C9:$N9),IF(Assumptions!$B$5=3,Seasonal_Profile!D$11,IF($C9=1,IF(Assumptions!$B$10=2,Assumptions!F$18*IF(Assumptions!$B$5=1,Seasonal_Profile!D$8,Seasonal_Profile!D$10)/IF(Assumptions!$B$5=1,SUMPRODUCT(Assumptions!$D$18:$O$18,Seasonal_Profile!$B$8:$M$8),SUMPRODUCT(Assumptions!$D$18:$O$18,Seasonal_Profile!$B$10:$M$10)),Assumptions!F$18/SUM(Assumptions!$D$18:$O$18)),IF(Assumptions!$B$5=1,Seasonal_Profile!D$8,Seasonal_Profile!D$10)))) | G9: =IF(SUM(Monthly_Override!$C9:$N9)>0,Monthly_Override!F9/SUM(Monthly_Override!$C9:$N9),IF(Assumptions!$B$5=3,Seasonal_Profile!E$11,IF($C9=1,IF(Assumptions!$B$10=2,Assumptions!G$18*IF(Assumptions!$B$5=1,Seasonal_Profile!E$8,Seasonal_Profile!E$10)/IF(Assumptions!$B$5=1,SUMPRODUCT(Assumptions!$D$18:$O$18,Seasonal_Profile!$B$8:$M$8),SUMPRODUCT(Assumptions!$D$18:$O$18,Seasonal_Profile!$B$10:$M$10)),Assumptions!G$18/SUM(Assumptions!$D$18:$O$18)),IF(Assumptions!$B$5=1,Seasonal_Profile!E$8,Seasonal_Profile!E$10)))) | H9: =IF(SUM(Monthly_Override!$C9:$N9)>0,Monthly_Override!G9/SUM(Monthly_Override!$C9:$N9),IF(Assumptions!$B$5=3,Seasonal_Profile!F$11,IF($C9=1,IF(Assumptions!$B$10=2,Assumptions!H$18*IF(Assumptions!$B$5=1,Seasonal_Profile!F$8,Seasonal_Profile!F$10)/IF(Assumptions!$B$5=1,SUMPRODUCT(Assumptions!$D$18:$O$18,Seasonal_Profile!$B$8:$M$8),SUMPRODUCT(Assumptions!$D$18:$O$18,Seasonal_Profile!$B$10:$M$10)),Assumptions!H$18/SUM(Assumptions!$D$18:$O$18)),IF(Assumptions!$B$5=1,Seasonal_Profile!F$8,Seasonal_Profile!F$10)))) | I9: =IF(SUM(Monthly_Override!$C9:$N9)>0,Monthly_Override!H9/SUM(Monthly_Override!$C9:$N9),IF(Assumptions!$B$5=3,Seasonal_Profile!G$11,IF($C9=1,IF(Assumptions!$B$10=2,Assumptions!I$18*IF(Assumptions!$B$5=1,Seasonal_Profile!G$8,Seasonal_Profile!G$10)/IF(Assumptions!$B$5=1,SUMPRODUCT(Assumptions!$D$18:$O$18,Seasonal_Profile!$B$8:$M$8),SUMPRODUCT(Assumptions!$D$18:$O$18,Seasonal_Profile!$B$10:$M$10)),Assumptions!I$18/SUM(Assumptions!$D$18:$O$18)),IF(Assumptions!$B$5=1,Seasonal_Profile!G$8,Seasonal_Profile!G$10)))) | J9: =IF(SUM(Monthly_Override!$C9:$N9)>0,Monthly_Override!I9/SUM(Monthly_Override!$C9:$N9),IF(Assumptions!$B$5=3,Seasonal_Profile!H$11,IF($C9=1,IF(Assumptions!$B$10=2,Assumptions!J$18*IF(Assumptions!$B$5=1,Seasonal_Profile!H$8,Seasonal_Profile!H$10)/IF(Assumptions!$B$5=1,SUMPRODUCT(Assumptions!$D$18:$O$18,Seasonal_Profile!$B$8:$M$8),SUMPRODUCT(Assumptions!$D$18:$O$18,Seasonal_Profile!$B$10:$M$10)),Assumptions!J$18/SUM(Assumptions!$D$18:$O$18)),IF(Assumptions!$B$5=1,Seasonal_Profile!H$8,Seasonal_Profile!H$10)))) | K9: =IF(SUM(Monthly_Override!$C9:$N9)>0,Monthly_Override!J9/SUM(Monthly_Override!$C9:$N9),IF(Assumptions!$B$5=3,Seasonal_Profile!I$11,IF($C9=1,IF(Assumptions!$B$10=2,Assumptions!K$18*IF(Assumptions!$B$5=1,Seasonal_Profile!I$8,Seasonal_Profile!I$10)/IF(Assumptions!$B$5=1,SUMPRODUCT(Assumptions!$D$18:$O$18,Seasonal_Profile!$B$8:$M$8),SUMPRODUCT(Assumptions!$D$18:$O$18,Seasonal_Profile!$B$10:$M$10)),Assumptions!K$18/SUM(Assumptions!$D$18:$O$18)),IF(Assumptions!$B$5=1,Seasonal_Profile!I$8,Seasonal_Profile!I$10)))) | ... O9: =IF(SUM(Monthly_Override!$C9:$N9)>0,Monthly_Override!N9/SUM(Monthly_Override!$C9:$N9),IF(Assumptions!$B$5=3,Seasonal_Profile!M$11,IF($C9=1,IF(Assumptions!$B$10=2,Assumptions!O$18*IF(Assumptions!$B$5=1,Seasonal_Profile!M$8,Seasonal_Profile!M$10)/IF(Assumptions!$B$5=1,SUMPRODUCT(Assumptions!$D$18:$O$18,Seasonal_Profile!$B$8:$M$8),SUMPRODUCT(Assumptions!$D$18:$O$18,Seasonal_Profile!$B$10:$M$10)),Assumptions!O$18/SUM(Assumptions!$D$18:$O$18)),IF(Assumptions!$B$5=1,Seasonal_Profile!M$8,Seasonal_Profile!M$10)))) | P9: =SUM(D9:O9)
A10: San Fabian | B10: 2024 | C10: =Assumptions!C19 | D10: =IF(SUM(Monthly_Override!$C10:$N10)>0,Monthly_Override!C10/SUM(Monthly_Override!$C10:$N10),IF(Assumptions!$B$5=3,Seasonal_Profile!B$11,IF($C10=1,IF(Assumptions!$B$10=2,Assumptions!D$19*IF(Assumptions!$B$5=1,Seasonal_Profile!B$8,Seasonal_Profile!B$10)/IF(Assumptions!$B$5=1,SUMPRODUCT(Assumptions!$D$19:$O$19,Seasonal_Profile!$B$8:$M$8),SUMPRODUCT(Assumptions!$D$19:$O$19,Seasonal_Profile!$B$10:$M$10)),Assumptions!D$19/SUM(Assumptions!$D$19:$O$19)),IF(Assumptions!$B$5=1,Seasonal_Profile!B$8,Seasonal_Profile!B$10)))) | E10: =IF(SUM(Monthly_Override!$C10:$N10)>0,Monthly_Override!D10/SUM(Monthly_Override!$C10:$N10),IF(Assumptions!$B$5=3,Seasonal_Profile!C$11,IF($C10=1,IF(Assumptions!$B$10=2,Assumptions!E$19*IF(Assumptions!$B$5=1,Seasonal_Profile!C$8,Seasonal_Profile!C$10)/IF(Assumptions!$B$5=1,SUMPRODUCT(Assumptions!$D$19:$O$19,Seasonal_Profile!$B$8:$M$8),SUMPRODUCT(Assumptions!$D$19:$O$19,Seasonal_Profile!$B$10:$M$10)),Assumptions!E$19/SUM(Assumptions!$D$19:$O$19)),IF(Assumptions!$B$5=1,Seasonal_Profile!C$8,Seasonal_Profile!C$10)))) | F10: =IF(SUM(Monthly_Override!$C10:$N10)>0,Monthly_Override!E10/SUM(Monthly_Override!$C10:$N10),IF(Assumptions!$B$5=3,Seasonal_Profile!D$11,IF($C10=1,IF(Assumptions!$B$10=2,Assumptions!F$19*IF(Assumptions!$B$5=1,Seasonal_Profile!D$8,Seasonal_Profile!D$10)/IF(Assumptions!$B$5=1,SUMPRODUCT(Assumptions!$D$19:$O$19,Seasonal_Profile!$B$8:$M$8),SUMPRODUCT(Assumptions!$D$19:$O$19,Seasonal_Profile!$B$10:$M$10)),Assumptions!F$19/SUM(Assumptions!$D$19:$O$19)),IF(Assumptions!$B$5=1,Seasonal_Profile!D$8,Seasonal_Profile!D$10)))) | G10: =IF(SUM(Monthly_Override!$C10:$N10)>0,Monthly_Override!F10/SUM(Monthly_Override!$C10:$N10),IF(Assumptions!$B$5=3,Seasonal_Profile!E$11,IF($C10=1,IF(Assumptions!$B$10=2,Assumptions!G$19*IF(Assumptions!$B$5=1,Seasonal_Profile!E$8,Seasonal_Profile!E$10)/IF(Assumptions!$B$5=1,SUMPRODUCT(Assumptions!$D$19:$O$19,Seasonal_Profile!$B$8:$M$8),SUMPRODUCT(Assumptions!$D$19:$O$19,Seasonal_Profile!$B$10:$M$10)),Assumptions!G$19/SUM(Assumptions!$D$19:$O$19)),IF(Assumptions!$B$5=1,Seasonal_Profile!E$8,Seasonal_Profile!E$10)))) | H10: =IF(SUM(Monthly_Override!$C10:$N10)>0,Monthly_Override!G10/SUM(Monthly_Override!$C10:$N10),IF(Assumptions!$B$5=3,Seasonal_Profile!F$11,IF($C10=1,IF(Assumptions!$B$10=2,Assumptions!H$19*IF(Assumptions!$B$5=1,Seasonal_Profile!F$8,Seasonal_Profile!F$10)/IF(Assumptions!$B$5=1,SUMPRODUCT(Assumptions!$D$19:$O$19,Seasonal_Profile!$B$8:$M$8),SUMPRODUCT(Assumptions!$D$19:$O$19,Seasonal_Profile!$B$10:$M$10)),Assumptions!H$19/SUM(Assumptions!$D$19:$O$19)),IF(Assumptions!$B$5=1,Seasonal_Profile!F$8,Seasonal_Profile!F$10)))) | I10: =IF(SUM(Monthly_Override!$C10:$N10)>0,Monthly_Override!H10/SUM(Monthly_Override!$C10:$N10),IF(Assumptions!$B$5=3,Seasonal_Profile!G$11,IF($C10=1,IF(Assumptions!$B$10=2,Assumptions!I$19*IF(Assumptions!$B$5=1,Seasonal_Profile!G$8,Seasonal_Profile!G$10)/IF(Assumptions!$B$5=1,SUMPRODUCT(Assumptions!$D$19:$O$19,Seasonal_Profile!$B$8:$M$8),SUMPRODUCT(Assumptions!$D$19:$O$19,Seasonal_Profile!$B$10:$M$10)),Assumptions!I$19/SUM(Assumptions!$D$19:$O$19)),IF(Assumptions!$B$5=1,Seasonal_Profile!G$8,Seasonal_Profile!G$10)))) | J10: =IF(SUM(Monthly_Override!$C10:$N10)>0,Monthly_Override!I10/SUM(Monthly_Override!$C10:$N10),IF(Assumptions!$B$5=3,Seasonal_Profile!H$11,IF($C10=1,IF(Assumptions!$B$10=2,Assumptions!J$19*IF(Assumptions!$B$5=1,Seasonal_Profile!H$8,Seasonal_Profile!H$10)/IF(Assumptions!$B$5=1,SUMPRODUCT(Assumptions!$D$19:$O$19,Seasonal_Profile!$B$8:$M$8),SUMPRODUCT(Assumptions!$D$19:$O$19,Seasonal_Profile!$B$10:$M$10)),Assumptions!J$19/SUM(Assumptions!$D$19:$O$19)),IF(Assumptions!$B$5=1,Seasonal_Profile!H$8,Seasonal_Profile!H$10)))) | K10: =IF(SUM(Monthly_Override!$C10:$N10)>0,Monthly_Override!J10/SUM(Monthly_Override!$C10:$N10),IF(Assumptions!$B$5=3,Seasonal_Profile!I$11,IF($C10=1,IF(Assumptions!$B$10=2,Assumptions!K$19*IF(Assumptions!$B$5=1,Seasonal_Profile!I$8,Seasonal_Profile!I$10)/IF(Assumptions!$B$5=1,SUMPRODUCT(Assumptions!$D$19:$O$19,Seasonal_Profile!$B$8:$M$8),SUMPRODUCT(Assumptions!$D$19:$O$19,Seasonal_Profile!$B$10:$M$10)),Assumptions!K$19/SUM(Assumptions!$D$19:$O$19)),IF(Assumptions!$B$5=1,Seasonal_Profile!I$8,Seasonal_Profile!I$10)))) | ... O10: =IF(SUM(Monthly_Override!$C10:$N10)>0,Monthly_Override!N10/SUM(Monthly_Override!$C10:$N10),IF(Assumptions!$B$5=3,Seasonal_Profile!M$11,IF($C10=1,IF(Assumptions!$B$10=2,Assumptions!O$19*IF(Assumptions!$B$5=1,Seasonal_Profile!M$8,Seasonal_Profile!M$10)/IF(Assumptions!$B$5=1,SUMPRODUCT(Assumptions!$D$19:$O$19,Seasonal_Profile!$B$8:$M$8),SUMPRODUCT(Assumptions!$D$19:$O$19,Seasonal_Profile!$B$10:$M$10)),Assumptions!O$19/SUM(Assumptions!$D$19:$O$19)),IF(Assumptions!$B$5=1,Seasonal_Profile!M$8,Seasonal_Profile!M$10)))) | P10: =SUM(D10:O10)
